Workbook

Sheet Quotation
A1: QUOTATION
A2: S.P. INDUSTRIES
A3: Plot No-97, Sector No - 7, PCNTDA, MIDC Bhosari, Pune - 411 026
A4: Mob no -09823714674
A5: SPECIAL PURPOSE MACHINES/FIXTURES DESIGN & MANUFACTURING, REVERSE ENGINEERING, PRECISION ENGINEERING WORK, CAD SERVICES
A7: To, | D7: Your Inquiry No.
A8: Sidel India Pvt. Ltd. | D8: Quotation No. :- SP-04220
A9: Plot No. B-19, MIDC, Chakan Industrial Area | D9: Date :- 27/11/2025
A10: Mahalunga Village, Taluka Khed, District Pune – 410501, Maharashtra, India
A11: Dear Sir,
A12: We Thank you for your enquiry & have pleasure in quotation below for your requirement.
A13: Sr No | B13: Drawing No. | C13: Description | D13: QTY | E13: Unit Rate | F13: Value
E14: Rs Ps | F14: Rs Ps | G14: Remark
A15: 1 | B15: 9000011003 | C15: COOLING RAIL SUPPORT PLATE ( | D15: 16 | E15: =+'SHEET 2'!U3 -> 236.4328 | F15: =+E15*D15 -> 3782.9248
A16: 2 | B16: 9000011103 | C16: COOLING RAIL SUPPORT PLATE ( | D16: 8 | E16: =+'SHEET 2'!U4 -> 248.3992 | F16: =+E16*D16 -> 1987.1936
A17: 3 | B17: 9000118001 | C17: SPACER FOR AIR COLLECTOR 40 RUBIN (0425@ | D17: 8 | E17: =+'SHEET 2'!U5 -> 392.55732 | F17: =+E17*D17 -> 3140.4586
A18: 4 | B18: 9000152202 | C18: 1/2N CLAMP UNIT PINION HOLDING BLOCK | D18: 1 | E18: =+'SHEET 2'!U6 -> 3783.9648 | F18: =+E18*D18 -> 3783.9648
A19: 5 | B19: 9000166101 | C19: CENTER HEATER STAND COVER TOP SIDE | D19: 1 | E19: =+'SHEET 2'!U7 -> 913.8455 | F19: =+E19*D19 -> 913.8455
A20: 6 | B20: 9000182703 | C20: SPRING FOR CLAMP UNIT FOR 1/4N | D20: 16 | E20: =+'SHEET 2'!U8 -> 750 | F20: =+E20*D20 -> 12000
A21: 7 | B21: 9000184102 | C21: CYLINDER EXTENSION FOR SLIDING PLATE | D21: 8 | E21: =+'SHEET 2'!U9 -> 927.87705 | F21: =+E21*D21 -> 7423.0164
A22: 8 | B22: 9000197803 | C22: TIE BAR LOCKING | D22: 8 | E22: =+'SHEET 2'!U10 -> 4251.5635 | F22: =+E22*D22 -> 34012.508
A23: 9 | B23: 9000229001 | C23: EJECTOR JAW HOLDING PLATE | D23: 24 | E23: =+'SHEET 2'!U11 -> 104.3175 | F23: =+E23*D23 -> 2503.62
A24: 10 | B24: 9000234902 | C24: SPACER FOR NORGREN VALVE MTG.BRACKET | D24: 4 | E24: =+'SHEET 2'!U12 -> 235.26367 | F24: =+E24*D24 -> 941.05469
A25: 11 | B25: 9000236502 | C25: BLOW PIN BUSH SR 1/2 | D25: 4 | E25: =+'SHEET 2'!U13 -> 0 | F25: =+E25*D25 -> 0 | G25: UB MATERIAL NOT CLEAR
A26: 12 | B26: 9000392401 | C26: BOLT FOR LOADER TIE BAR | D26: 14 | E26: =+'SHEET 2'!U14 -> 183.68273 | F26: =+E26*D26 -> 2571.5583
A27: 13 | B27: 9000392901 | C27: LOADER GRIPPER HOLDING PLATE FOR 1-4GRE@ | D27: 7 | E27: =+'SHEET 2'!U15 -> 7843.875 | F27: =+E27*D27 -> 54907.125
A28: 14 | B28: 9000513803 | C28: BLOW PIN BUSH | D28: 8 | E28: =+'SHEET 2'!U16 -> 3094.7726 | F28: =+E28*D28 -> 24758.181
A29: 15 | B29: 9000569303 | C29: TIE-BAR LOCKING PLATE | D29: 4 | E29: =+'SHEET 2'!U17 -> 5257.6619 | F29: =+E29*D29 -> 21030.647
A30: 16 | B30: 9000574302 | C30: INDEX 1聽 SUPPORT PLATE | D30: 4 | E30: =+'SHEET 2'!U18 -> 477.00094 | F30: =+E30*D30 -> 1908.0038
A31: 17 | B31: 9000650903 | C31: PREFORM SCALE SUPPORT PLATE | D31: 4 | E31: =+'SHEET 2'!U19 -> 7745.4688 | F31: =+E31*D31 -> 30981.875
A32: 18 | B32: 9000692404 | C32: TENSIONER BEARING SHAFT FOR BOTTLE | D32: 2 | E32: =+'SHEET 2'!U20 -> 641.73175 | F32: =+E32*D32 -> 1283.4635
A33: 19 | B33: 9000692703 | C33: TENSIONER BEARING SHAFT - 75H | D33: 6 | E33: =+'SHEET 2'!U21 -> 702.16469 | F33: =+E33*D33 -> 4212.9881
A34: 20 | B34: 9000700403 | C34: BOTTLE EJECTOR CYLINDER MTG. PLATE | D34: 1 | E34: =+'SHEET 2'!U22 -> 1162.2591 | F34: =+E34*D34 -> 1162.2591
A35: 21 | B35: 9000722603 | C35: SUPPORT BEARING MTG. PLATE | D35: 16 | E35: =+'SHEET 2'!U23 -> 2656.9336 | F35: =+E35*D35 -> 42510.938
A36: 22 | B36: 9000734304 | C36: CAM BASE PLATE MOUNTING BEAM | D36: 1 | E36: =+'SHEET 2'!U24 -> 16562.5 | F36: =+E36*D36 -> 16562.5
A37: 23 | B37: 9000736504 | C37: BRACKET FOR PHOTOCELL & REFLECTOR | D37: 1 | E37: =+'SHEET 2'!U25 -> 1249 | F37: =+E37*D37 -> 1249
... A46: 32 | B46: 9001301502 | C46: STOPPER NYLONE FOR SHUTTLE | D46: 2 | E46: =+'SHEET 2'!U34 -> 283.41 | F46: =+E46*D46 -> 566.82
A47: 33 | B47: 9001301702 | C47: MOUNTING LOWER PLATE FOR EXTRUSION MOUNT | D47: 4 | E47: =+'SHEET 2'!U35 -> 0 | F47: =+E47*D47 -> 0 | G47: DRAWING REQUIRED
A48: 34 | B48: 9001309502 | C48: PLATE FOR WEDGE CLAMP | D48: 64 | E48: =+'SHEET 2'!U36 -> 514.28 | F48: =+E48*D48 -> 32913.92
A49: 35 | B49: 9001312101 | C49: BASE PLATE FOR LOADER | D49: 7 | E49: =+'SHEET 2'!U37 -> 6072.56 | F49: =+E49*D49 -> 42507.92
...

Sheet SHEET 2
A2: Sr No | B2: Drawing No. | C2: Description | D2: Material | E2: Material Size | H2: Wight | I2: Material Cost | J2: CNC / Turning | K2: Milling/Cutting | L2: VMC | M2: Drilling | N2: Taping | O2: Grinding | P2: Laser Cutting & Bending | Q2: Sparking/HRC/WELD | R2: Finish | S2: Profit &over heads | T2: Qty | U2: Unit price | V2: Total Price | X2: REMARK
A3: 1 | B3: 9000011003 | C3: COOLING RAIL SUPPORT PLATE ( | D3: Alu 6060 | E3: 12 | F3: 32 | G3: 40 | H3: =+E3*F3*G3*2.77/1000000 -> 0.0425472 | I3: =H3*450 -> 19.14624 | J3: 0 | K3: 120 | L3: 0 | M3: 50 | N3: 0 | O3: 0 | P3: 0 | Q3: 0 | R3: 0 | S3: =SUM(I3:R3)*25% -> 47.28656 | T3: 16 | U3: =+SUM(I3:S3) -> 236.4328 | V3: =U3*T3 -> 3782.9248
A4: 2 | B4: 9000011103 | C4: COOLING RAIL SUPPORT PLATE ( | D4: Alu 6060 | E4: 12 | F4: 32 | G4: 60 | H4: =+E4*F4*G4*2.77/1000000 -> 0.0638208 | I4: =H4*450 -> 28.71936 | J4: 0 | K4: 120 | L4: 0 | M4: 50 | N4: 0 | O4: 0 | P4: 0 | Q4: 0 | R4: 0 | S4: =SUM(I4:R4)*25% -> 49.67984 | T4: 8 | U4: =+SUM(I4:S4) -> 248.3992 | V4: =U4*T4 -> 1987.1936
A5: 3 | B5: 9000118001 | C5: SPACER FOR AIR COLLECTOR 40 RUBIN (0425@ | D5: SS316L | E5: 25 | G5: 30 | H5: =+E5*E5*3.14/4*G5*8.55/1000000 -> 0.12584531 | I5: =H5*350 -> 44.045859 | J5: 220 | K5: 0 | L5: 0 | M5: 50 | N5: 0 | O5: 0 | P5: 0 | Q5: 0 | R5: 0 | S5: =SUM(I5:R5)*25% -> 78.511465 | T5: 8 | U5: =+SUM(I5:S5) -> 392.55732 | V5: =U5*T5 -> 3140.4586
A6: 4 | B6: 9000152202 | C6: 1/2N CLAMP UNIT PINION HOLDING BLOCK | D6: MS | E6: 160 | F6: 120 | G6: 55 | H6: =+E6*F6*G6*7.85/1000000 -> 8.2896 | I6: =H6*90 -> 746.064 | J6: 0 | K6: 300 | L6: 1600 | M6: 100 | N6: 100 | O6: 100 | P6: 0 | Q6: 0 | R6: =+H6*25 -> 207.24 | S6: =SUM(I6:R6)*20% -> 630.6608 | T6: 1 | U6: =+SUM(I6:S6) -> 3783.9648 | V6: =U6*T6 -> 3783.9648
A7: 5 | B7: 9000166101 | C7: CENTER HEATER STAND COVER TOP SIDE | D7: ALU | E7: 65 | F7: 65 | G7: 16 | H7: =+E7*F7*G7*2.77/1000000 -> 0.187252 | I7: =H7*450 -> 84.2634 | J7: 0 | K7: 120 | L7: 400 | M7: 0 | N7: 80 | O7: 0 | P7: 0 | Q7: 0 | R7: =+H7*250 -> 46.813 | S7: =SUM(I7:R7)*25% -> 182.7691 | T7: 1 | U7: =+SUM(I7:S7) -> 913.8455 | V7: =U7*T7 -> 913.8455
A8: 6 | B8: 9000182703 | C8: SPRING FOR CLAMP UNIT FOR 1/4N | D8: STD | E8: 0 | F8: 0 | G8: 0 | H8: =+E8*F8*G8*7.85/1000000 -> 0 | I8: =H8*100 -> 0 | J8: 600 | K8: 0 | L8: 0 | M8: 0 | N8: 0 | O8: 0 | P8: 0 | Q8: 0 | R8: =H8*25 -> 0 | S8: =SUM(I8:R8)*25% -> 150 | T8: 16 | U8: =+SUM(I8:S8) -> 750 | V8: =U8*T8 -> 12000
A9: 7 | B9: 9000184102 | C9: CYLINDER EXTENSION FOR SLIDING PLATE | D9: MS | E9: 32 | G9: 265 | H9: =+E9*E9*3.14/4*G9*7.85/1000000 -> 1.6721882 | I9: =H9*90 -> 150.49693 | J9: 450 | K9: 80 | L9: 0 | M9: 0 | N9: 20 | O9: 0 | P9: 0 | Q9: 0 | R9: =+H9*25 -> 41.804704 | S9: =SUM(I9:R9)*25% -> 185.57541 | T9: 8 | U9: =+SUM(I9:S9) -> 927.87705 | V9: =U9*T9 -> 7423.0164
A10: 8 | B10: 9000197803 | C10: TIE BAR LOCKING | D10: Alu 6060 | E10: 55 | F10: 55 | G10: 605 | H10: =+E10*F10*G10*2.77/1000000 -> 5.0694463 | I10: =+H10*450 -> 2281.2508 | J10: 0 | K10: 600 | L10: 0 | M10: =16*25 -> 400 | N10: =6*20 -> 120 | O10: 0 | P10: 0 | Q10: 0 | R10: 0 | S10: =SUM(I10:R10)*25% -> 850.3127 | T10: 8 | U10: =+SUM(I10:S10) -> 4251.5635 | V10: =U10*T10 -> 34012.508
A11: 9 | B11: 9000229001 | C11: EJECTOR JAW HOLDING PLATE | D11: MS | E11: 40 | F11: 20 | G11: 5 | H11: =+E11*F11*G11*7.85/1000000 -> 0.0314 | I11: =H11*90 -> 2.826 | J11: 0 | K11: 0 | L11: 0 | M11: 0 | N11: 0 | O11: 0 | P11: 80 | Q11: 0 | R11: =+H11*20 -> 0.628 | S11: =SUM(I11:R11)*25% -> 20.8635 | T11: 24 | U11: =+SUM(I11:S11) -> 104.3175 | V11: =U11*T11 -> 2503.62
A12: 10 | B12: 9000234902 | C12: SPACER FOR NORGREN VALVE MTG.BRACKET | D12: MS | E12: 50 | F12: 25 | G12: 25 | H12: =+E12*F12*G12*7.85/1000000 -> 0.2453125 | I12: =H12*90 -> 22.078125 | J12: 0 | K12: 80 | L12: 0 | M12: 40 | N12: 40 | O12: 0 | P12: 0 | Q12: 0 | R12: =H12*25 -> 6.1328125 | S12: =SUM(I12:R12)*25% -> 47.052734 | T12: 4 | U12: =+SUM(I12:S12) -> 235.26367 | V12: =U12*T12 -> 941.05469
A13: 11 | B13: 9000236502 | C13: BLOW PIN BUSH SR 1/2 | D13: UB | E13: 0 | G13: 0 | H13: =+E13*E13*3.14/4*G13*7.85/1000000 -> 0 | I13: =H13*100 -> 0 | J13: 0 | K13: 0 | L13: 0 | M13: 0 | N13: 0 | O13: 0 | P13: 0 | Q13: 0 | R13: 0 | S13: =SUM(I13:R13)*25% -> 0 | T13: 4 | U13: =+SUM(I13:S13) -> 0 | V13: =U13*T13 -> 0 | W13: UB MATERIAL NOT CLEAR
A14: 12 | B14: 9000392401 | C14: BOLT FOR LOADER TIE BAR | D14: EN8 | E14: 20 | G14: 55 | H14: =+E14*E14*3.14/4*G14*7.85/1000000 -> 0.1355695 | I14: =H14*100 -> 13.55695 | J14: 120 | K14: 0 | L14: 0 | M14: 0 | N14: 0 | O14: 0 | P14: 0 | Q14: 10 | R14: =H14*25 -> 3.3892375 | S14: =SUM(I14:R14)*25% -> 36.736547 | T14: 14 | U14: =+SUM(I14:S14) -> 183.68273 | V14: =U14*T14 -> 2571.5583
A15: 13 | B15: 9000392901 | C15: LOADER GRIPPER HOLDING PLATE FOR 1-4GRE@ | D15: ALU | E15: 445 | F15: 225 | G15: 20 | H15: =+E15*F15*G15*2.55/1000000 -> 5.106375 | I15: =+H15*450 -> 2297.8688 | J15: 0 | K15: 750 | L15: 1200 | M15: =6*20 -> 120 | N15: 120 | O15: 0 | P15: 0 | Q15: 0 | R15: =+H15*350 -> 1787.2313 | S15: =SUM(I15:R15)*25% -> 1568.775 | T15: 7 | U15: =+SUM(I15:S15) -> 7843.875 | V15: =U15*T15 -> 54907.125
A16: 14 | B16: 9000513803 | C16: BLOW PIN BUSH | D16: PET | E16: 90 | G16: 90 | H16: =+E16*E16*3.14/4*G16*1.77/1000000 -> 1.012909 | I16: =H16*2000 -> 2025.8181 | J16: 450 | K16: 0 | L16: 0 | M16: 0 | N16: 0 | O16: 0 | P16: 0 | Q16: 0 | R16: 0 | S16: =SUM(I16:R16)*25% -> 618.95452 | T16: 8 | U16: =+SUM(I16:S16) -> 3094.7726 | V16: =U16*T16 -> 24758.181
A17: 15 | B17: 9000569303 | C17: TIE-BAR LOCKING PLATE | D17: MS | E17: 760 | F17: 65 | G17: 55 | H17: =+E17*F17*G17*7.85/1000000 -> 21.32845 | I17: =H17*90 -> 1919.5605 | J17: 0 | K17: 1200 | L17: 0 | M17: =20*25 -> 500 | N17: =8*20 -> 160 | O17: 0 | P17: 0 | Q17: 0 | R17: =+H17*20 -> 426.569 | S17: =SUM(I17:R17)*25% -> 1051.5324 | T17: 4 | U17: =+SUM(I17:S17) -> 5257.6619 | V17: =U17*T17 -> 21030.647
A18: 16 | B18: 9000574302 | C18: INDEX 1聽 SUPPORT PLATE | D18: MS | E18: 105 | F18: 30 | G18: 30 | H18: =+E18*F18*G18*7.85/1000000 -> 0.741825 | I18: =H18*90 -> 66.76425 | J18: 0 | K18: 160 | L18: 0 | M18: 100 | N18: 40 | O18: 0 | P18: 0 | Q18: 0 | R18: =+H18*20 -> 14.8365 | S18: =SUM(I18:R18)*25% -> 95.400188 | T18: 4 | U18: =+SUM(I18:S18) -> 477.00094 | V18: =U18*T18 -> 1908.0038
A19: 17 | B19: 9000650903 | C19: PREFORM SCALE SUPPORT PLATE | D19: MS | E19: 3500 | F19: 50 | G19: 10 | H19: =+E19*F19*G19*7.85/1000000 -> 13.7375 | I19: =+H19*90 -> 1236.375 | J19: 0 | K19: 0 | L19: =8*400 -> 3200 | M19: =8*20 -> 160 | N19: =40*20 -> 800 | O19: 0 | P19: 0 | Q19: 0 | R19: 800 | S19: =SUM(I19:R19)*25% -> 1549.0938 | T19: 4 | U19: =+SUM(I19:S19) -> 7745.4688 | V19: =U19*T19 -> 30981.875
A20: 18 | B20: 9000692404 | C20: TENSIONER BEARING SHAFT FOR BOTTLE | D20: MS | E20: 40 | G20: 100 | H20: =+E20*E20*3.14/4*G20*7.85/1000000 -> 0.98596 | I20: =+H20*90 -> 88.7364 | J20: 180 | K20: 80 | L20: 0 | M20: 0 | N20: 20 | O20: 120 | P20: 0 | Q20: 0 | R20: =+H20*25 -> 24.649 | S20: =SUM(I20:R20)*25% -> 128.34635 | T20: 2 | U20: =+SUM(I20:S20) -> 641.73175 | V20: =U20*T20 -> 1283.4635
A21: 19 | B21: 9000692703 | C21: TENSIONER BEARING SHAFT - 75H | D21: MS | E21: 40 | G21: 125 | H21: =+E21*E21*3.14/4*G21*7.85/1000000 -> 1.23245 | I21: =+H21*90 -> 110.9205 | J21: 200 | K21: 80 | L21: 0 | M21: 0 | N21: 20 | O21: 120 | P21: 0 | Q21: 0 | R21: =+H21*25 -> 30.81125 | S21: =SUM(I21:R21)*25% -> 140.43294 | T21: 6 | U21: =+SUM(I21:S21) -> 702.16469 | V21: =U21*T21 -> 4212.9881
A22: 20 | B22: 9000700403 | C22: BOTTLE EJECTOR CYLINDER MTG. PLATE | D22: MS | E22: 165 | F22: 95 | G22: 12 | H22: =+E22*F22*G22*7.85/1000000 -> 1.476585 | I22: =H22*90 -> 132.89265 | J22: 0 | K22: 160 | L22: 400 | M22: 0 | N22: =4*20 -> 80 | O22: 120 | P22: 0 | Q22: 0 | R22: =+H22*25 -> 36.914625 | S22: =SUM(I22:R22)*25% -> 232.45182 | T22: 1 | U22: =+SUM(I22:S22) -> 1162.2591 | V22: =U22*T22 -> 1162.2591
A23: 21 | B23: 9000722603 | C23: SUPPORT BEARING MTG. PLATE | D23: C45 | E23: 85 | F23: 125 | G23: 60 | H23: =+E23*F23*G23*7.85/1000000 -> 5.004375 | I23: =H23*100 -> 500.4375 | J23: 0 | K23: 220 | L23: 1200 | M23: 0 | N23: 80 | O23: 0 | P23: 0 | Q23: 0 | R23: =+H23*25 -> 125.10937 | S23: =SUM(I23:R23)*25% -> 531.38672 | T23: 16 | U23: =+SUM(I23:S23) -> 2656.9336 | V23: =U23*T23 -> 42510.938
A24: 22 | B24: 9000734304 | C24: CAM BASE PLATE MOUNTING BEAM | D24: MS | E24: 0 | F24: 0 | G24: 0 | H24: 43 | I24: 3855 | J24: 800 | K24: 1600 | L24: 3200 | M24: 0 | N24: =7*20 -> 140 | O24: 0 | P24: 0 | Q24: =43*60 -> 2580 | R24: =43*25 -> 1075 | S24: =SUM(I24:R24)*25% -> 3312.5 | T24: 1 | U24: =+SUM(I24:S24) -> 16562.5 | V24: =U24*T24 -> 16562.5
A25: 23 | B25: 9000736504 | C25: BRACKET FOR PHOTOCELL & REFLECTOR | D25: MS | E25: 700 | F25: 100 | G25: 10 | H25: =+E25*F25*G25*7.85/1000000 -> 5.495 | I25: =H25*90 -> 494.55 | J25: 0 | K25: 0 | L25: 0 | M25: 0 | N25: 40 | O25: 0 | P25: 800 | Q25: 0 | R25: =+H25*25 -> 137.375 | S25: =SUM(I25:R25)*25% -> 367.98125 | T25: 1 | U25: 1249 | V25: =U25*T25 -> 1249
A26: 24 | B26: 9000745006 | C26: C CHANNEL 1 | E26: 0 | F26: 0 | G26: 0 | H26: =+E26*F26*G26*7.85/1000000 -> 0 | I26: =H26*200 -> 0 | J26: 0 | K26: 0 | L26: 0 | M26: 0 | N26: 0 | O26: 0 | P26: 0 | Q26: 0 | R26: 200 | S26: =SUM(I26:R26)*25% -> 50 | T26: 2 | U26: =+SUM(I26:S26) -> 250 | V26: =U26*T26 -> 500
A27: 25 | B27: 9000745203 | C27: U - BRACKET FOR SPINDLE GUIDE SYSTEM | D27: MS | E27: 600 | F27: 150 | G27: 14 | H27: =+E27*F27*G27*7.85/1000000 -> 9.891 | I27: =+H27*90 -> 890.19 | J27: 0 | K27: 1200 | L27: 2400 | M27: 0 | N27: 120 | O27: 1200 | P27: 0 | Q27: 400 | R27: =+H27*25 -> 247.275 | S27: =SUM(I27:R27)*25% -> 1614.3663 | T27: 10 | U27: =+SUM(I27:S27) -> 8071.8313 | V27: =U27*T27 -> 80718.312
A28: 26 | B28: 9000746303 | C28: SPINDLE ROLLER GUIDE SUPPORT FOR IDLER @ | E28: 0 | F28: 0 | G28: 0 | H28: =+E28*F28*G28*7.85/1000000 -> 0 | I28: =H28*Z27 -> 0 | J28: 0 | K28: 0 | L28: 0 | M28: 0 | N28: 0 | O28: 0 | P28: 0 | Q28: 0 | R28: 0 | S28: =SUM(I28:R28)*25% -> 0 | T28: 1 | U28: 4000 | V28: =U28*T28 -> 4000 | X28: OLD RATE
A29: 27 | B29: 9000780902 | C29: GUIDE ROD | D29: EN24 | E29: 40 | G29: 165 | H29: =+E29*E29*3.14/4*G29*7.85/1000000 -> 1.626834 | I29: =+H29*120 -> 195.22008 | J29: 550 | K29: 80 | L29: 0 | M29: 0 | N29: 0 | O29: 0 | P29: 0 | Q29: 0 | R29: =+H29*25 -> 40.67085 | S29: =SUM(I29:R29)*25% -> 216.47273 | T29: 5 | U29: =+SUM(I29:S29) -> 1082.3637 | V29: =U29*T29 -> 5411.8183
A30: 28 | B30: 9001245102 | C30: SENSOR BASE MOUTING PLATE | D30: SS304 | E30: 450 | F30: 100 | G30: 6 | H30: =+E30*F30*G30*8.55/1000000 -> 2.3085 | I30: =+H30*320 -> 738.72 | J30: 0 | K30: 0 | L30: 0 | M30: 0 | N30: 0 | O30: 0 | P30: 250 | Q30: 0 | R30: 100 | S30: =SUM(I30:R30)*25% -> 272.18 | T30: 3 | U30: =+SUM(I30:S30) -> 1360.9 | V30: =U30*T30 -> 4082.7
A31: 29 | B31: 9001284403 | C31: BRACKET FOR SPINDLE GUIDE SYSTEM | D31: MS | E31: 450 | F31: 105 | G31: 25 | H31: =+E31*F31*G31*7.85/1000000 -> 9.2728125 | I31: =+H31*90 -> 834.55313 | J31: 0 | K31: 800 | L31: 1200 | M31: 0 | N31: 0 | O31: 1200 | P31: 0 | Q31: 350 | R31: =+H31*25 -> 231.82031 | S31: =SUM(I31:R31)*25% -> 1154.0934 | T31: 4 | U31: =+SUM(I31:S31) -> 5770.4668 | V31: =U31*T31 -> 23081.867
A32: 30 | B32: 9001293301 | C32: STUD FOR ADJUSTABLE TAKEOFF SUPPORT | D32: MS | E32: 14 | G32: 210 | H32: =+E32*E32*3.14/4*G32*7.85/1000000 -> 0.25363821 | I32: =H32*100 -> 25.363821 | J32: 160 | K32: 0 | L32: 80 | M32: 0 | N32: 0 | O32: 0 | P32: 0 | Q32: 0 | R32: 20 | S32: =SUM(I32:R32)*25% -> 71.340955 | T32: 8 | U32: =+SUM(I32:S32) -> 356.70478 | V32: =U32*T32 -> 2853.6382 | X32: OLD RATE
A33: 31 | B33: 9001300304 | C33: PLATE FOR VERTICAL 90MM PITCH | D33: MS | E33: 375 | F33: 200 | G33: 16 | H33: =+E33*F33*G33*7.85/1000000 -> 9.42 | I33: =H33*90 -> 847.8 | J33: 0 | K33: 650 | L33: 1200 | M33: 50 | N33: =8*20 -> 160 | O33: 0 | P33: 0 | Q33: 0 | R33: =+H33*25 -> 235.5 | S33: =SUM(I33:R33)*25% -> 785.825 | T33: 1 | U33: =+SUM(I33:S33) -> 3929.125 | V33: =U33*T33 -> 3929.125
A34: 32 | B34: 9001301502 | C34: STOPPER NYLONE FOR SHUTTLE | D34: POLYAMIDE | E34: 55 | F34: 30 | G34: 20 | H34: =+E34*F34*G34*1.77/1000000 -> 0.05841 | I34: =H34*800 -> 46.728 | J34: 0 | K34: 100 | L34: 0 | M34: 80 | N34: 0 | O34: 0 | P34: 0 | Q34: 0 | R34: 0 | S34: =SUM(I34:R34)*25% -> 56.682 | T34: 2 | U34: =+SUM(I34:S34) -> 283.41 | V34: =U34*T34 -> 566.82
A35: 33 | B35: 9001301702 | C35: MOUNTING LOWER PLATE FOR EXTRUSION MOUNT | E35: 0 | F35: 0 | G35: 0 | H35: =+E35*F35*G35*7.85/1000000 -> 0 | I35: =H35*200 -> 0 | J35: 0 | K35: 0 | L35: 0 | M35: 0 | N35: 0 | O35: 0 | P35: 0 | Q35: 0 | R35: 0 | S35: =SUM(I35:R35)*25% -> 0 | T35: 4 | U35: =+SUM(I35:S35) -> 0 | V35: =U35*T35 -> 0 | W35: DRAWING REQUIRED
A36: 34 | B36: 9001309502 | C36: PLATE FOR WEDGE CLAMP | D36: 100CR6 | E36: 80 | F36: 20 | G36: 20 | H36: =+E36*F36*G36*7.85/1000000 -> 0.2512 | I36: =H36*120 -> 30.144 | J36: 0 | K36: 200 | L36: 0 | M36: =6*25 -> 150 | N36: 0 | O36: 0 | P36: 0 | Q36: 25 | R36: =+H36*25 -> 6.28 | S36: =SUM(I36:R36)*25% -> 102.856 | T36: 64 | U36: =+SUM(I36:S36) -> 514.28 | V36: =U36*T36 -> 32913.92
A37: 35 | B37: 9001312101 | C37: BASE PLATE FOR LOADER | D37: MS | E37: 555 | F37: 165 | G37: 18 | H37: =+E37*F37*G37*7.85/1000000 -> 12.939547 | I37: =H37*90 -> 1164.5593 | J37: 0 | K37: 650 | L37: =6*400 -> 2400 | M37: 0 | N37: =16*20 -> 320 | O37: 0 | P37: 0 | Q37: 0 | R37: =+H37*25 -> 323.48869 | S37: =SUM(I37:R37)*25% -> 1214.512 | T37: 7 | U37: =+SUM(I37:S37) -> 6072.56 | V37: =U37*T37 -> 42507.92
A38: 36 | B38: 9001312202 | C38: BLOCK FOR SYF BEARING LOADER | D38: ALU 7075 | E38: 122 | F38: 40 | G38: 55 | H38: =+E38*F38*G38*2.77/1000000 -> 0.743468 | I38: =H38*450 -> 334.5606 | J38: 0 | K38: 150 | L38: 0 | M38: =6*25 -> 150 | N38: 0 | O38: 0 | P38: 0 | Q38: 0 | R38: =+H38*150 -> 111.5202 | S38: =SUM(I38:R38)*25% -> 186.5202 | T38: 7 | U38: =+SUM(I38:S38) -> 932.601 | V38: =U38*T38 -> 6528.207
A39: 37 | B39: 9001312302 | C39: BLOCK FOR SYF BEARING GEAR SIDE | D39: ALU 7075 | E39: 122 | F39: 70 | G39: 40 | H39: =+E39*F39*G39*2.77/1000000 -> 0.946232 | I39: =H39*450 -> 425.8044 | J39: 0 | K39: 220 | L39: 0 | M39: =9*25 -> 225 | N39: 60 | O39: 0 | P39: 0 | Q39: 0 | R39: =+H39*150 -> 141.9348 | S39: =SUM(I39:R39)*25% -> 268.1848 | T39: 7 | U39: =+SUM(I39:S39) -> 1340.924 | V39: =U39*T39 -> 9386.468
A40: 38 | B40: 9001312402 | C40: PLATE FOR LOADER MTG. | D40: MS | E40: 265 | F40: 78 | G40: 25 | H40: =+E40*F40*G40*7.85/1000000 -> 4.0564875 | I40: =H40*90 -> 365.08388 | J40: 0 | K40: 350 | L40: 200 | M40: 0 | N40: 60 | O40: 0 | P40: 0 | Q40: 0 | R40: =+H40*25 -> 101.41219 | S40: =SUM(I40:R40)*25% -> 269.12402 | T40: 14 | U40: =+SUM(I40:S40) -> 1345.6201 | V40: =U40*T40 -> 18838.681
A41: 39 | B41: 9001312501 | C41: BOLT FOR STOPER LONG 140MM | D41: MS | E41: 20 | G41: 145 | H41: =+E41*E41*3.14/4*G41*7.85/1000000 -> 0.3574105 | I41: =H41*100 -> 35.74105 | J41: 250 | K41: 80 | L41: 0 | M41: 0 | N41: 0 | O41: 0 | P41: 0 | Q41: 0 | R41: =+H41*25 -> 8.9352625 | S41: =SUM(I41:R41)*25% -> 93.669078 | T41: 7 | U41: =+SUM(I41:S41) -> 468.34539 | V41: =U41*T41 -> 3278.4177
...

Sheet 22
A1: Sr No | B1: Drawing No. | C1: Description | D1: Material | E1: Material Size | H1: Wight | I1: Material Cost
A2: 1 | B2: 9000734304 | D2: ms | E2: 220 | F2: 230 | G2: 20 | H2: =+E2*F2*G2*7.85/1000000 -> 7.9442 | I2: =H2*90 -> 714.978
A3: 2 | B3: 9000734304 | D3: ms | E3: 325 | F3: 200 | G3: 16 | H3: =+E3*F3*G3*7.85/1000000 -> 8.164 | I3: =H3*90 -> 734.76
A4: 3 | B4: 9000734304 | D4: ms | E4: 325 | F4: 200 | G4: 16 | H4: =+E4*F4*G4*7.85/1000000 -> 8.164 | I4: =H4*90 -> 734.76
A5: 4 | B5: 9000734304 | D5: ms | E5: 80 | F5: 120 | G5: 16 | H5: =+E5*F5*G5*7.85/1000000 -> 1.20576 | I5: =H5*90 -> 108.5184
A6: 5 | B6: 9000734304 | D6: ms | E6: 45 | F6: 70 | G6: 25 | H6: =+E6*F6*G6*7.85/1000000 -> 0.6181875 | I6: =H6*90 -> 55.636875
A7: 7 | B7: 9000734304 | D7: ms | E7: 365 | G7: 20 | H7: =+E7*E7*3.14/4*G7*8/1000000 -> 16.73306 | I7: =H7*90 -> 1505.9754
H8: =SUM(H2:H7) -> 42.829207 | I8: =SUM(I2:I7) -> 3854.6287

Sheet 25
A1: Sr No | B1: Drawing No. | C1: Description | D1: Material | E1: Material Size | H1: Wight | I1: Material Cost
A2: 1 | B2: 9000745203 | D2: MS | E2: 225 | F2: 110 | G2: 20 | H2: =+E2*F2*G2*7.85/1000000 -> 3.88575 | I2: =H2*90 -> 349.7175
A3: 2 | B3: 9000745203 | E3: 185 | F3: 110 | G3: 30 | H3: =+E3*F3*G3*7.85/1000000 -> 4.792425 | I3: =H3*90 -> 431.31825
A4: 3 | B4: 9000745203 | E4: 55 | F4: 100 | G4: 16 | H4: =+E4*F4*G4*7.85/1000000 -> 0.6908 | I4: =H4*90 -> 62.172

Sheet 29
A1: Sr No | B1: Drawing No. | C1: Description | D1: Material | E1: Material Size | H1: Wight | I1: Material Cost
A2: 1 | B2: 9000745203 | D2: ss | E2: 310 | F2: 120 | G2: 25 | H2: =+E2*F2*G2*7.85/1000000 -> 7.3005 | I2: =H2*90 -> 657.045
A3: 2 | B3: 9000745203 | D3: ss | E3: 130 | F3: 85 | G3: 12 | H3: =+E3*F3*G3*7.85/1000000 -> 1.04091 | I3: =H3*90 -> 93.6819
A4: 3 | B4: 9000745203 | D4: ss | E4: 35 | F4: 85 | G4: 12 | H4: =+E4*F4*G4*7.85/1000000 -> 0.280245 | I4: =H4*90 -> 25.22205

Sheet 62
A1: Sr No | B1: Drawing No. | C1: Description | D1: Material | E1: Material Size | H1: Wight | I1: Material Cost
A2: 1 | B2: 9000745203 | D2: ss | E2: 110 | F2: 40 | G2: 8 | H2: =+E2*F2*G2*7.85/1000000 -> 0.27632 | I2: =H2*90 -> 24.8688
A3: 2 | B3: 9000745203 | D3: ss | E3: 100 | F3: 40 | G3: 8 | H3: =+E3*F3*G3*7.85/1000000 -> 0.2512 | I3: =H3*90 -> 22.608

Sheet SHEET 3
B3: Material | C3: Short Text | D3: Qty
B4: 9000011003 | C4: COOLING RAIL SUPPORT PLATE ( | D4: 16
B5: 9000011103 | C5: COOLING RAIL SUPPORT PLATE ( | D5: 8
B6: 9000118001 | C6: SPACER FOR AIR COLLECTOR 40 RUBIN (0425@ | D6: 8
B7: 9000152202 | C7: 1/2N CLAMP UNIT PINION HOLDING BLOCK | D7: 1
B8: 9000166101 | C8: CENTER HEATER STAND COVER TOP SIDE | D8: 1
B9: 9000182703 | C9: SPRING FOR CLAMP UNIT FOR 1/4N | D9: 16
B10: 9000184102 | C10: CYLINDER EXTENSION FOR SLIDING PLATE | D10: 8
B11: 9000197803 | C11: TIE BAR LOCKING | D11: 8
B12: 9000229001 | C12: EJECTOR JAW HOLDING PLATE | D12: 24
B13: 9000234902 | C13: SPACER FOR NORGREN VALVE MTG.BRACKET | D13: 4
B14: 9000236502 | C14: BLOW PIN BUSH SR 1/2 | D14: 4
B15: 9000392401 | C15: BOLT FOR LOADER TIE BAR | D15: 14
... B106: 9001861501 | C106: BUSH (SPIDER)_12.7_SR 5/2 | D106: 2
