Workbook

Sheet Quotation
A1: QUOTATION
A2: S.P. INDUSTRIES
A3: Plot No-97, Sector No - 7, PCNTDA, MIDC Bhosari, Pune - 411 026
A4: Mob no -09823714674
A5: SPECIAL PURPOSE MACHINES/FIXTURES DESIGN & MANUFACTURING, REVERSE ENGINEERING, PRECISION ENGINEERING WORK, CAD SERVICES
A7: To, | D7: Your Inquiry No.
A8: Sidel India Pvt. Ltd. | D8: Quotation No. :- SP-04340
A9: Plot No. B-19, MIDC, Chakan Industrial Area | D9: Date :- 15/11/2025
A10: Mahalunga Village, Taluka Khed, District Pune – 410501, Maharashtra, India
A11: Dear Sir,
A12: We Thank you for your enquiry & have pleasure in quotation below for your requirement.
A13: Sr No | B13: Drawing No. | C13: Description | D13: QTY | E13: Unit Rate | F13: Value
E14: Rs Ps | F14: Rs Ps
A15: 1 | B15: 4327059803 | C15: GRIP CAM SUPPORT DP720 4B ONE | D15: 1 | E15: ='4327059803'!V13 -> 36771.84 | F15: =E15*D15 -> 36771.84
A17: 2 | B17: 4327083503 | C17: ASSY CAM SUPPORT DP1080 ONE | D17: 1 | E17: ='4327083503'!V21 -> 70281.33 | F17: =E17*D17 -> 70281.33
A19: 3 | B19: 4327033201 | C19: ASSY SUPPORT FLANGE DP 720 ONE | D19: 1 | E19: ='4327033201'!V8 -> 166063.8 | F19: =E19*D19 -> 166063.8
A20: 6
A21: 7 | B21: 4322369101 | C21: ASSY SUPPORT ARM DP.1080 | D21: 1 | E21: ='4322369101'!V11 -> 36058.68 | F21: =E21*D21 -> 36058.68
A22: 8
A23: 9 | B23: 4353703501 | C23: GRIP CAM SUPPORT DP720 ONE | D23: 1 | E23: ='4353703501'!V14 -> 99843.66 | F23: =E23*D23 -> 99843.66
A24: 10
A25: 11 | B25: 4332033801 | C25: GRIP CAM SUPPORT DP720 4B ONE | D25: 1 | E25: ='4332033801'!V13 -> 33339.18 | F25: =E25*D25 -> 33339.18
A26: 12
A27: 13
A28: 14
A29: 15
A30: 16
D31: Total | F31: =SUM(F15:F30) -> 442358.49
A32: Terms & Conditions
A33: Prices quoted are for Ex-Works
A34: Packing & Forwarding Charges Will be extra
A35: GST : 18 % extra
A36: Delivery :4 to 6 weeks from the date of receipt of your technically & commercially confirmed clear purchase order.
A37: Payment Terms : Against Delivery
A38: Validity :This quotation hold good for acceptance for 30days after which it is subject to our confirmation.
A39: We hope that the above is clear & look forward to the pleasure of receiving your valuable order at the earliest.
A40: For S.P.INDUSTRIES

Sheet Sheet1
A1: Explosion level | B1: Item Number | C1: Component number | D1: Object description | E1: Additional Info | F1: Qty | G1: Unit | H1: Remark
A2: .1 | B2: 3P32 | C2: 4327059803 | D2: GRIP CAM SUPPORT DP720 4B ONE | F2: 1 | G2: PCE | H2: Assembly to quote
A3: ..2 | B3: 0001 | C3: 4326161703 | D3: ADJUSTING FLAT CAMMA 720 | F3: 1 | G3: PCE | H3: Quoted
A4: ..2 | B4: 0002 | C4: 4326153101 | D4: GRIP CAM 720 | F4: 2 | G4: PCE | H4: Quoted
A5: ..2 | B5: 0003 | C5: 193801 | D5: SCREW ISO4017-M10X020-A2-70 | F5: 3 | G5: PCE
A6: ..2 | B6: 0004 | C6: 179634 | D6: WASHER DIN7349-L10-A2 | F6: 7 | G6: PCE
A7: ..2 | B7: 0005 | C7: 193803 | D7: SCREW ISO4017-M10X045-A2-70 | F7: 4 | G7: PCE
A8: ..2 | B8: 0006 | C8: 4326493701 | D8: SPACER | F8: 4 | G8: PCE
A9: ..2 | B9: 0007 | C9: 80000HSP008 | D9: ELASTIC PIN | E9: SPIN.ELA.I304-6873- 4X25 | F9: 4 | G9: PCE
A10: .1 | B10: 3P33 | C10: 4327083503 | D10: ASSY CAM SUPPORT DP1080 ONE | F10: 1 | G10: PCE | H10: Assembly to quote
A11: ..2 | B11: 0001 | C11: 4326300403 | D11: ADJUSTING FLAT CAMMA 1080 | F11: 1 | G11: PCE | H11: Quoted
A12: ..2 | B12: 0002 | C12: 4326339601 | D12: GRIP CAM 1080 | F12: 2 | G12: PCE | H12: Quoted
A13: ..2 | B13: 0003 | C13: 193801 | D13: SCREW ISO4017-M10X020-A2-70 | F13: 4 | G13: PCE
A14: ..2 | B14: 0004 | C14: 179634 | D14: WASHER DIN7349-L10-A2 | F14: 8 | G14: PCE
A15: ..2 | B15: 0005 | C15: 193803 | D15: SCREW ISO4017-M10X045-A2-70 | F15: 4 | G15: PCE
A16: ..2 | B16: 0006 | C16: 4326493701 | D16: SPACER | F16: 4 | G16: PCE
A17: ..2 | B17: 0007 | C17: 80000HSP008 | D17: ELASTIC PIN | F17: 4 | G17: PCE
A18: ..2 | B18: 0008 | C18: 4326322401 | D18: ASSY COUNTER-CAM STELLA 1080 | F18: 1 | G18: PCE
A19: ...3 | B19: 0001 | C19: 4326281201 | D19: COUNTER-CAM 1080 | F19: 1 | G19: PCE | H19: Quoted
A20: ...3 | B20: 0002 | C20: 4326283501 | D20: LOCKING SPACER CONTROCAMMA | F20: 2 | G20: PCE | H20: Quoted
A21: ...3 | B21: 0003 | C21: 123819 | D21: WASHER ISO7094-08-100HV-A2 | F21: 2 | G21: PCE
A22: ...3 | B22: 0004 | C22: 193836 | D22: SCREW ISO4017-M08X020-A2-70 | F22: 2 | G22: PCE
A23: ...3 | B23: 0005 | C23: 80000HSP004 | D23: PIN | E23: SPIN.ELA.I304-6873- 4X16 | F23: 2 | G23: PCE
A24: ...3 | B24: 0006 | C24: 123836 | D24: WASHER ISO7089-08-200HV-A2 | F24: 2 | G24: PCE
A25: ...3 | B25: 0007 | C25: 188435 | D25: SCREW ISO4017-M08X016-A2-70 | F25: 2 | G25: PCE
A26: .1 | B26: 3P35 | C26: 4327033201 | D26: ASSY SUPPORT FLANGE DP 720 ONE | F26: 5 | G26: PCE | H26: Assembly to quote
A27: ..2 | B27: 0001 | C27: 4326335201 | D27: SUPPORT FLANGE | F27: 5 | G27: PCE | H27: Quoted
A28: ..2 | B28: 0002 | C28: 193814 | D28: SCREW ISO4017-M16X045-A2-70 | F28: 15 | G28: PCE
A29: ..2 | B29: 0003 | C29: 114246 | D29: WASHER ISO7089-16-200HV-A2 | F29: 15 | G29: PCE
A30: .1 | B30: 3P37 | C30: 4322369101 | D30: ASSY SUPPORT ARM DP.1080 | F30: 1 | G30: PCE | H30: Assembly to quote
A31: ..2 | B31: 0001 | C31: 4292669201 | D31: COLUMN ARM DP 1080 | F31: 4 | G31: PCE | H31: Quoted
A32: ..2 | B32: 0002 | C32: 194131 | D32: SCREW ISO4017-M12X040-A2-70 | F32: 4 | G32: PCE
A33: ..2 | B33: 0003 | C33: 4285817301 | D33: WASHER D40X12.5X3 | F33: 4 | G33: PCE
A34: ..2 | B34: 0004 | C34: 103738 | D34: SCREW ISO4017-M16X035-A2-70 | F34: 4 | G34: PCE
A35: ..2 | B35: 0005 | C35: 114246 | D35: WASHER ISO7089-16-200HV-A2 | F35: 4 | G35: PCE
A36: ..2 | B36: 0006 | C36: 80000HSL208 | D36: PEG I304-1707 6X20 | E36: PINA CILINDRICA - UNI 1707 - D.6X20 IN ACC.INOX AISI 304 | F36: 8 | G36: PCE
A37: .1 | B37: 3P49 | C37: 4353703501 | D37: GRIP CAM SUPPORT DP720 ONE | F37: 3 | G37: PCE | H37: Assembly to quote
A38: ..2 | B38: 0001 | C38: 4353702901 | D38: ADJUSTING FLAT CAMMA DP720 | F38: 3 | G38: PCE | H38: Quoted
A39: ..2 | B39: 0002 | C39: 4326153101 | D39: GRIP CAM 720 | F39: 6 | G39: PCE
A40: ..2 | B40: 0003 | C40: 193801 | D40: SCREW ISO4017-M10X020-A2-70 | F40: 9 | G40: PCE
...

Sheet 4327059803
A2: Sr no | B2: Drg no | C2: Description | D2: Material | E2: Material Size | H2: Wight | I2: Material Cost | J2: CNC / Turning | K2: Milling/Cutting | L2: VMC | M2: Drilling | N2: Taping | O2: Grinding | P2: Welding/ Hardness | Q2: Lasure/Wire cutting | R2: Finish | S2: Profit &over heads | T2: Qty | U2: Unit price | V2: Total Price
A3: 1 | B3: 4327059803 | C3: GRIP CAM SUPPORT DP720 4B ONE | E3: 0 | F3: 0 | G3: 0 | H3: =+E3*F3*G3*8.55/1000000 -> 0 | I3: =H3*320 -> 0 | J3: 0 | K3: 0 | L3: 0 | M3: 0 | N3: 0 | O3: 0 | P3: 0 | Q3: 0 | R3: =H3*30 -> 0 | S3: =SUM(I3:R3)*20% -> 0 | T3: 1 | U3: =+SUM(I3:S3) -> 0 | V3: =U3*T3 -> 0
A4: 2 | B4: 4326161703 | C4: ADJUSTING FLAT CAMMA 720 | E4: 0 | F4: 0 | G4: 0 | H4: =+E4*F4*G4*8.55/1000000 -> 0 | I4: 0 | J4: 0 | K4: 0 | L4: 0 | M4: 0 | N4: 0 | O4: 0 | P4: 0 | Q4: 0 | R4: =H4*30 -> 0 | S4: =SUM(I4:R4)*20% -> 0 | T4: 1 | U4: 24884 | V4: =U4*T4 -> 24884
A5: 3 | B5: 4326153101 | C5: GRIP CAM 720 | E5: 0 | F5: 0 | G5: 0 | H5: =+E5*F5*G5*8.55/1000000 -> 0 | I5: 0 | J5: 0 | K5: 0 | L5: 0 | M5: 0 | N5: 0 | O5: 0 | P5: 0 | Q5: 0 | R5: =H5*30 -> 0 | S5: =SUM(I5:R5)*20% -> 0 | T5: 2 | U5: 4462 | V5: =U5*T5 -> 8924
A6: 4 | B6: 193801 | C6: SCREW ISO4017-M10X020-A2-70 | E6: 0 | F6: 0 | G6: 0 | H6: =+E6*F6*G6*8.55/1000000 -> 0 | I6: 30 | J6: 0 | K6: 0 | L6: 0 | M6: 0 | N6: 0 | O6: 0 | P6: 0 | Q6: 0 | R6: =H6*30 -> 0 | S6: =SUM(I6:R6)*20% -> 6 | T6: 3 | U6: =+SUM(I6:S6) -> 36 | V6: =U6*T6 -> 108
A7: 5 | B7: 179634 | C7: WASHER DIN7349-L10-A2 | E7: 0 | F7: 0 | G7: 0 | H7: =+E7*F7*G7*8.55/1000000 -> 0 | I7: 10 | J7: 0 | K7: 0 | L7: 0 | M7: 0 | N7: 0 | O7: 0 | P7: 0 | Q7: 0 | R7: =H7*30 -> 0 | S7: =SUM(I7:R7)*20% -> 2 | T7: 7 | U7: =+SUM(I7:S7) -> 12 | V7: =U7*T7 -> 84
A8: 6 | B8: 193803 | C8: SCREW ISO4017-M10X045-A2-70 | E8: 0 | F8: 0 | G8: 0 | H8: =+E8*F8*G8*8.55/1000000 -> 0 | I8: 30 | J8: 0 | K8: 0 | L8: 0 | M8: 0 | N8: 0 | O8: 0 | P8: 0 | Q8: 0 | R8: =H8*30 -> 0 | S8: =SUM(I8:R8)*20% -> 6 | T8: 4 | U8: =+SUM(I8:S8) -> 36 | V8: =U8*T8 -> 144
A9: 7 | B9: 4326493701 | C9: SPACER | E9: 0 | F9: 0 | G9: 0 | H9: =+E9*F9*G9*8.55/1000000 -> 0 | I9: =H9*320 -> 0 | J9: 0 | K9: 0 | L9: 0 | M9: 0 | N9: 0 | O9: 0 | P9: 0 | Q9: 0 | R9: =H9*30 -> 0 | S9: =SUM(I9:R9)*20% -> 0 | T9: 4 | U9: 200 | V9: =U9*T9 -> 800
A10: 8 | B10: 80000HSP008 | C10: ELASTIC PIN | E10: 0 | F10: 0 | G10: 0 | H10: =+E10*F10*G10*8.55/1000000 -> 0 | I10: 16 | J10: 0 | K10: 0 | L10: 0 | M10: 0 | N10: 0 | O10: 0 | P10: 0 | Q10: 0 | R10: =H10*30 -> 0 | S10: =SUM(I10:R10)*20% -> 3.2 | T10: 4 | U10: =+SUM(I10:S10) -> 19.2 | V10: =U10*T10 -> 76.8
V11: =SUM(V3:V10) -> 35020.8
U12: Assembly Cost | V12: =V11*5% -> 1751.04
U13: Total | V13: =SUM(V11:V12) -> 36771.84

Sheet 4327083503
A2: Sr no | B2: Drg no | C2: Description | D2: Material | E2: Material Size | H2: Wight | I2: Material Cost | J2: CNC / Turning | K2: Milling/Cutting | L2: VMC | M2: Drilling | N2: Taping | O2: Grinding | P2: Welding/ Hardness | Q2: Lasure/Wire cutting | R2: Finish | S2: Profit &over heads | T2: Qty | U2: Unit price | V2: Total Price
A3: 1 | B3: 4327083503 | C3: ASSY CAM SUPPORT DP1080 ONE | E3: 0 | F3: 0 | G3: 0 | H3: =+E3*F3*G3*8.55/1000000 -> 0 | I3: =H3*320 -> 0 | J3: 0 | K3: 0 | L3: 0 | M3: 0 | N3: 0 | O3: 0 | P3: 0 | Q3: 0 | R3: =H3*30 -> 0 | S3: =SUM(I3:R3)*20% -> 0 | T3: 1 | U3: =+SUM(I3:S3) -> 0 | V3: =U3*T3 -> 0
A4: 2 | B4: 4326300403 | C4: ADJUSTING FLAT CAMMA 1080 | E4: 0 | F4: 0 | G4: 0 | H4: =+E4*F4*G4*8.55/1000000 -> 0 | I4: 0 | J4: 0 | K4: 0 | L4: 0 | M4: 0 | N4: 0 | O4: 0 | P4: 0 | Q4: 0 | R4: =H4*30 -> 0 | S4: =SUM(I4:R4)*20% -> 0 | T4: 1 | U4: 48841 | V4: =U4*T4 -> 48841
A5: 3 | B5: 4326339601 | C5: GRIP CAM 1080 | E5: 0 | F5: 0 | G5: 0 | H5: =+E5*F5*G5*8.55/1000000 -> 0 | I5: 0 | J5: 0 | K5: 0 | L5: 0 | M5: 0 | N5: 0 | O5: 0 | P5: 0 | Q5: 0 | R5: =H5*30 -> 0 | S5: =SUM(I5:R5)*20% -> 0 | T5: 2 | U5: 5427 | V5: =U5*T5 -> 10854
A6: 4 | B6: 193801 | C6: SCREW ISO4017-M10X020-A2-70 | E6: 0 | F6: 0 | G6: 0 | H6: =+E6*F6*G6*8.55/1000000 -> 0 | I6: 30 | J6: 0 | K6: 0 | L6: 0 | M6: 0 | N6: 0 | O6: 0 | P6: 0 | Q6: 0 | R6: =H6*30 -> 0 | S6: =SUM(I6:R6)*20% -> 6 | T6: 4 | U6: =+SUM(I6:S6) -> 36 | V6: =U6*T6 -> 144
A7: 5 | B7: 179634 | C7: WASHER DIN7349-L10-A2 | E7: 0 | F7: 0 | G7: 0 | H7: =+E7*F7*G7*8.55/1000000 -> 0 | I7: 12 | J7: 0 | K7: 0 | L7: 0 | M7: 0 | N7: 0 | O7: 0 | P7: 0 | Q7: 0 | R7: =H7*30 -> 0 | S7: =SUM(I7:R7)*20% -> 2.4 | T7: 8 | U7: =+SUM(I7:S7) -> 14.4 | V7: =U7*T7 -> 115.2
A8: 6 | B8: 193803 | C8: SCREW ISO4017-M10X045-A2-70 | E8: 0 | F8: 0 | G8: 0 | H8: =+E8*F8*G8*8.55/1000000 -> 0 | I8: 30 | J8: 0 | K8: 0 | L8: 0 | M8: 0 | N8: 0 | O8: 0 | P8: 0 | Q8: 0 | R8: =H8*30 -> 0 | S8: =SUM(I8:R8)*20% -> 6 | T8: 4 | U8: =+SUM(I8:S8) -> 36 | V8: =U8*T8 -> 144
A9: 7 | B9: 4326493701 | C9: SPACER | E9: 0 | F9: 0 | G9: 0 | H9: =+E9*F9*G9*8.55/1000000 -> 0 | I9: =H9*320 -> 0 | J9: 0 | K9: 0 | L9: 0 | M9: 0 | N9: 0 | O9: 0 | P9: 0 | Q9: 0 | R9: =H9*30 -> 0 | S9: =SUM(I9:R9)*20% -> 0 | T9: 4 | U9: 200 | V9: =U9*T9 -> 800
A10: 8 | B10: 80000HSP008 | C10: ELASTIC PIN | E10: 0 | F10: 0 | G10: 0 | H10: =+E10*F10*G10*8.55/1000000 -> 0 | I10: 16 | J10: 0 | K10: 0 | L10: 0 | M10: 0 | N10: 0 | O10: 0 | P10: 0 | Q10: 0 | R10: =H10*30 -> 0 | S10: =SUM(I10:R10)*20% -> 3.2 | T10: 4 | U10: =+SUM(I10:S10) -> 19.2 | V10: =U10*T10 -> 76.8
A11: 9 | B11: 4326322401 | C11: ASSY COUNTER-CAM STELLA 1080 | T11: 1 | U11: 0 | V11: 0 | W11: Assembly Drawing
A12: 10 | B12: 4326281201 | C12: COUNTER-CAM 1080 | T12: 1 | U12: 4414 | V12: =U12*T12 -> 4414
A13: 11 | B13: 4326283501 | C13: LOCKING SPACER CONTROCAMMA | T13: 2 | U13: 636 | V13: =U13*T13 -> 1272
A14: 12 | B14: 123819 | C14: WASHER ISO7094-08-100HV-A2 | E14: 0 | F14: 0 | G14: 0 | H14: =+E14*F14*G14*8.55/1000000 -> 0 | I14: 30 | J14: 0 | K14: 0 | L14: 0 | M14: 0 | N14: 0 | O14: 0 | P14: 0 | Q14: 0 | R14: =H14*30 -> 0 | S14: =SUM(I14:R14)*20% -> 6 | T14: 2 | U14: =+SUM(I14:S14) -> 36 | V14: =U14*T14 -> 72
A15: 13 | B15: 193836 | C15: SCREW ISO4017-M08X020-A2-70 | E15: 0 | F15: 0 | G15: 0 | H15: =+E15*F15*G15*8.55/1000000 -> 0 | I15: 25 | J15: 0 | K15: 0 | L15: 0 | M15: 0 | N15: 0 | O15: 0 | P15: 0 | Q15: 0 | R15: =H15*30 -> 0 | S15: =SUM(I15:R15)*20% -> 5 | T15: 2 | U15: =+SUM(I15:S15) -> 30 | V15: =U15*T15 -> 60
A16: 14 | B16: 80000HSP004 | C16: PIN | E16: 0 | F16: 0 | G16: 0 | H16: =+E16*F16*G16*8.55/1000000 -> 0 | I16: 22 | J16: 0 | K16: 0 | L16: 0 | M16: 0 | N16: 0 | O16: 0 | P16: 0 | Q16: 0 | R16: =H16*30 -> 0 | S16: =SUM(I16:R16)*20% -> 4.4 | T16: 2 | U16: =+SUM(I16:S16) -> 26.4 | V16: =U16*T16 -> 52.8
A17: 15 | B17: 123836 | C17: WASHER ISO7089-08-200HV-A2 | E17: 0 | F17: 0 | G17: 0 | H17: =+E17*F17*G17*8.55/1000000 -> 0 | I17: 12 | J17: 0 | K17: 0 | L17: 0 | M17: 0 | N17: 0 | O17: 0 | P17: 0 | Q17: 0 | R17: =H17*30 -> 0 | S17: =SUM(I17:R17)*20% -> 2.4 | T17: 2 | U17: =+SUM(I17:S17) -> 14.4 | V17: =U17*T17 -> 28.8
A18: 16 | B18: 188435 | C18: SCREW ISO4017-M08X016-A2-70 | E18: 0 | F18: 0 | G18: 0 | H18: =+E18*F18*G18*8.55/1000000 -> 0 | I18: 25 | J18: 0 | K18: 0 | L18: 0 | M18: 0 | N18: 0 | O18: 0 | P18: 0 | Q18: 0 | R18: =H18*30 -> 0 | S18: =SUM(I18:R18)*20% -> 5 | T18: 2 | U18: =+SUM(I18:S18) -> 30 | V18: =U18*T18 -> 60
V19: =SUM(V3:V18) -> 66934.6
U20: Assembly Cost | V20: =V19*5% -> 3346.73
U21: Total | V21: =SUM(V19:V20) -> 70281.33

Sheet 4327033201
A1: Sr no | B1: Drg no | C1: Description | D1: Material | E1: Material Size | H1: Wight | I1: Material Cost | J1: CNC / Turning | K1: Milling/Cutting | L1: VMC | M1: Drilling | N1: Taping | O1: Grinding | P1: Welding/ Hardness | Q1: Lasure/Wire cutting | R1: Finish | S1: Profit &over heads | T1: Qty | U1: Unit price | V1: Total Price
A2: 1 | B2: 4327033201 | C2: ASSY SUPPORT FLANGE DP 720 ONE | E2: 0 | F2: 0 | G2: 0 | H2: =+E2*F2*G2*8.55/1000000 -> 0 | I2: =H2*320 -> 0 | J2: 0 | K2: 0 | L2: 0 | M2: 0 | N2: 0 | O2: 0 | P2: 0 | Q2: 0 | R2: =H2*30 -> 0 | S2: =SUM(I2:R2)*20% -> 0 | T2: 5 | U2: =+SUM(I2:S2) -> 0 | V2: =U2*T2 -> 0
A3: 2 | B3: 4326335201 | C3: SUPPORT FLANGE | E3: 0 | F3: 0 | G3: 0 | H3: =+E3*F3*G3*8.55/1000000 -> 0 | I3: 0 | J3: 0 | K3: 0 | L3: 0 | M3: 0 | N3: 0 | O3: 0 | P3: 0 | Q3: 0 | R3: =H3*30 -> 0 | S3: =SUM(I3:R3)*20% -> 0 | T3: 5 | U3: 31300 | V3: =U3*T3 -> 156500
A4: 3 | B4: 193814 | C4: SCREW ISO4017-M16X045-A2-70 | E4: 0 | F4: 0 | G4: 0 | H4: =+E4*F4*G4*8.55/1000000 -> 0 | I4: 60 | J4: 0 | K4: 0 | L4: 0 | M4: 0 | N4: 0 | O4: 0 | P4: 0 | Q4: 0 | R4: =H4*30 -> 0 | S4: =SUM(I4:R4)*20% -> 12 | T4: 15 | U4: =+SUM(I4:S4) -> 72 | V4: =U4*T4 -> 1080
A5: 4 | B5: 114246 | C5: WASHER ISO7089-16-200HV-A2 | E5: 0 | F5: 0 | G5: 0 | H5: =+E5*F5*G5*8.55/1000000 -> 0 | I5: 32 | J5: 0 | K5: 0 | L5: 0 | M5: 0 | N5: 0 | O5: 0 | P5: 0 | Q5: 0 | R5: =H5*30 -> 0 | S5: =SUM(I5:R5)*20% -> 6.4 | T5: 15 | U5: =+SUM(I5:S5) -> 38.4 | V5: =U5*T5 -> 576
V6: =SUM(V2:V5) -> 158156
U7: Assembly Cost | V7: =V6*5% -> 7907.8
U8: Total | V8: =SUM(V6:V7) -> 166063.8

Sheet 4322369101
A1: Sr no | B1: Drg no | C1: Description | D1: Material | E1: Material Size | H1: Wight | I1: Material Cost | J1: CNC / Turning | K1: Milling/Cutting | L1: VMC | M1: Drilling | N1: Taping | O1: Grinding | P1: Welding/ Hardness | Q1: Lasure/Wire cutting | R1: Finish | S1: Profit &over heads | T1: Qty | U1: Unit price | V1: Total Price
A2: 1 | B2: 4322369101 | C2: ASSY SUPPORT ARM DP.1080 | E2: 0 | F2: 0 | G2: 0 | H2: =+E2*F2*G2*8.55/1000000 -> 0 | I2: =H2*320 -> 0 | J2: 0 | K2: 0 | L2: 0 | M2: 0 | N2: 0 | O2: 0 | P2: 0 | Q2: 0 | R2: =H2*30 -> 0 | S2: =SUM(I2:R2)*20% -> 0 | T2: 1 | U2: =+SUM(I2:S2) -> 0 | V2: =U2*T2 -> 0
A3: 2 | B3: 4292669201 | C3: COLUMN ARM DP 1080 | E3: 0 | F3: 0 | G3: 0 | H3: =+E3*F3*G3*8.55/1000000 -> 0 | I3: 0 | J3: 0 | K3: 0 | L3: 0 | M3: 0 | N3: 0 | O3: 0 | P3: 0 | Q3: 0 | R3: =H3*30 -> 0 | S3: =SUM(I3:R3)*20% -> 0 | T3: 4 | U3: 2808 | V3: =U3*T3 -> 11232
A4: 3 | B4: 194131 | C4: SCREW ISO4017-M12X040-A2-70 | E4: 0 | F4: 0 | G4: 0 | H4: =+E4*F4*G4*8.55/1000000 -> 0 | I4: 35 | J4: 0 | K4: 0 | L4: 0 | M4: 0 | N4: 0 | O4: 0 | P4: 0 | Q4: 0 | R4: =H4*30 -> 0 | S4: =SUM(I4:R4)*20% -> 7 | T4: 4 | U4: 5427 | V4: =U4*T4 -> 21708
A5: 4 | B5: 4285817301 | C5: WASHER D40X12.5X3 | E5: 0 | F5: 0 | G5: 0 | H5: =+E5*F5*G5*8.55/1000000 -> 0 | I5: 40 | J5: 0 | K5: 0 | L5: 0 | M5: 0 | N5: 0 | O5: 0 | P5: 0 | Q5: 0 | R5: =H5*30 -> 0 | S5: =SUM(I5:R5)*20% -> 8 | T5: 4 | U5: =+SUM(I5:S5) -> 48 | V5: =U5*T5 -> 192
A6: 5 | B6: 103738 | C6: SCREW ISO4017-M16X035-A2-70 | E6: 0 | F6: 0 | G6: 0 | H6: =+E6*F6*G6*8.55/1000000 -> 0 | I6: 50 | J6: 0 | K6: 0 | L6: 0 | M6: 0 | N6: 0 | O6: 0 | P6: 0 | Q6: 0 | R6: =H6*30 -> 0 | S6: =SUM(I6:R6)*20% -> 10 | T6: 4 | U6: =+SUM(I6:S6) -> 60 | V6: =U6*T6 -> 240
A7: 6 | B7: 114246 | C7: WASHER ISO7089-16-200HV-A2 | E7: 0 | F7: 0 | G7: 0 | H7: =+E7*F7*G7*8.55/1000000 -> 0 | I7: 22 | J7: 0 | K7: 0 | L7: 0 | M7: 0 | N7: 0 | O7: 0 | P7: 0 | Q7: 0 | R7: =H7*30 -> 0 | S7: =SUM(I7:R7)*20% -> 4.4 | T7: 4 | U7: =+SUM(I7:S7) -> 26.4 | V7: =U7*T7 -> 105.6
A8: 7 | B8: 80000HSL208 | C8: PEG I304-1707 6X20 (O ring) | E8: 0 | F8: 0 | G8: 0 | H8: =+E8*F8*G8*8.55/1000000 -> 0 | I8: 90 | J8: 0 | K8: 0 | L8: 0 | M8: 0 | N8: 0 | O8: 0 | P8: 0 | Q8: 0 | R8: =H8*30 -> 0 | S8: =SUM(I8:R8)*20% -> 18 | T8: 8 | U8: =+SUM(I8:S8) -> 108 | V8: =U8*T8 -> 864
V9: =SUM(V2:V8) -> 34341.6
U10: Assembly Cost | V10: =V9*5% -> 1717.08
U11: Total | V11: =SUM(V9:V10) -> 36058.68

Sheet 4353703501
A2: Sr no | B2: Drg no | C2: Description | D2: Material | E2: Material Size | H2: Wight | I2: Material Cost | J2: CNC / Turning | K2: Milling/Cutting | L2: VMC | M2: Drilling | N2: Taping | O2: Grinding | P2: Welding/ Hardness | Q2: Lasure/Wire cutting | R2: Finish | S2: Profit &over heads | T2: Qty | U2: Unit price | V2: Total Price
A3: 1 | B3: 4353703501 | C3: GRIP CAM SUPPORT DP720 ONE | E3: 0 | F3: 0 | G3: 0 | H3: =+E3*F3*G3*8.55/1000000 -> 0 | I3: =H3*320 -> 0 | J3: 0 | K3: 0 | L3: 0 | M3: 0 | N3: 0 | O3: 0 | P3: 0 | Q3: 0 | R3: =H3*30 -> 0 | S3: =SUM(I3:R3)*20% -> 0 | T3: 3 | U3: 0 | V3: =U3*T3 -> 0
A4: 2 | B4: 4353702901 | C4: ADJUSTING FLAT CAMMA DP720 | E4: 0 | F4: 0 | G4: 0 | H4: =+E4*F4*G4*8.55/1000000 -> 0 | I4: 0 | J4: 0 | K4: 0 | L4: 0 | M4: 0 | N4: 0 | O4: 0 | P4: 0 | Q4: 0 | R4: =H4*30 -> 0 | S4: =SUM(I4:R4)*20% -> 0 | T4: 3 | U4: 21526 | V4: =U4*T4 -> 64578
A5: 3 | B5: 4326153101 | C5: GRIP CAM 720 | E5: 0 | F5: 0 | G5: 0 | H5: =+E5*F5*G5*8.55/1000000 -> 0 | I5: 0 | J5: 0 | K5: 0 | L5: 0 | M5: 0 | N5: 0 | O5: 0 | P5: 0 | Q5: 0 | R5: =H5*30 -> 0 | S5: =SUM(I5:R5)*20% -> 0 | T5: 6 | U5: 4462 | V5: =U5*T5 -> 26772
A6: 4 | B6: 193801 | C6: SCREW ISO4017-M10X020-A2-70 | E6: 0 | F6: 0 | G6: 0 | H6: =+E6*F6*G6*8.55/1000000 -> 0 | I6: 20 | J6: 0 | K6: 0 | L6: 0 | M6: 0 | N6: 0 | O6: 0 | P6: 0 | Q6: 0 | R6: =H6*30 -> 0 | S6: =SUM(I6:R6)*20% -> 4 | T6: 9 | U6: =+SUM(I6:S6) -> 24 | V6: =U6*T6 -> 216
A7: 5 | B7: 179634 | C7: WASHER DIN7349-L10-A2 | E7: 0 | F7: 0 | G7: 0 | H7: =+E7*F7*G7*8.55/1000000 -> 0 | I7: 12 | J7: 0 | K7: 0 | L7: 0 | M7: 0 | N7: 0 | O7: 0 | P7: 0 | Q7: 0 | R7: =H7*30 -> 0 | S7: =SUM(I7:R7)*20% -> 2.4 | T7: 21 | U7: =+SUM(I7:S7) -> 14.4 | V7: =U7*T7 -> 302.4
A8: 6 | B8: 193803 | C8: SCREW ISO4017-M10X045-A2-70 | E8: 0 | F8: 0 | G8: 0 | H8: =+E8*F8*G8*8.55/1000000 -> 0 | I8: 35 | J8: 0 | K8: 0 | L8: 0 | M8: 0 | N8: 0 | O8: 0 | P8: 0 | Q8: 0 | R8: =H8*30 -> 0 | S8: =SUM(I8:R8)*20% -> 7 | T8: 12 | U8: =+SUM(I8:S8) -> 42 | V8: =U8*T8 -> 504
A9: 7 | B9: 4326493701 | C9: SPACER | E9: 0 | F9: 0 | G9: 0 | H9: =+E9*F9*G9*8.55/1000000 -> 0 | I9: =H9*320 -> 0 | J9: 0 | K9: 0 | L9: 0 | M9: 0 | N9: 0 | O9: 0 | P9: 0 | Q9: 0 | R9: =H9*30 -> 0 | S9: =SUM(I9:R9)*20% -> 0 | T9: 12 | U9: 200 | V9: =U9*T9 -> 2400
A10: 8 | B10: 80000HSP008 | C10: ELASTIC PIN | E10: 0 | F10: 0 | G10: 0 | H10: =+E10*F10*G10*8.55/1000000 -> 0 | I10: 22 | J10: 0 | K10: 0 | L10: 0 | M10: 0 | N10: 0 | O10: 0 | P10: 0 | Q10: 0 | R10: =H10*30 -> 0 | S10: =SUM(I10:R10)*20% -> 4.4 | T10: 12 | U10: =+SUM(I10:S10) -> 26.4 | V10: =U10*T10 -> 316.8
V12: =SUM(V3:V11) -> 95089.2
U13: Assembly Cost | V13: =V12*5% -> 4754.46
U14: Total | V14: =SUM(V12:V13) -> 99843.66

Sheet 4332033801
A2: Sr no | B2: Drg no | C2: Description | D2: Material | E2: Material Size | H2: Wight | I2: Material Cost | J2: CNC / Turning | K2: Milling/Cutting | L2: VMC | M2: Drilling | N2: Taping | O2: Grinding | P2: Welding/ Hardness | Q2: Lasure/Wire cutting | R2: Finish | S2: Profit &over heads | T2: Qty | U2: Unit price | V2: Total Price
A3: 1 | B3: 4332033801 | C3: GRIP CAM SUPPORT DP720 4B ONE | E3: 0 | F3: 0 | G3: 0 | H3: =+E3*F3*G3*8.55/1000000 -> 0 | I3: =H3*320 -> 0 | J3: 0 | K3: 0 | L3: 0 | M3: 0 | N3: 0 | O3: 0 | P3: 0 | Q3: 0 | R3: =H3*30 -> 0 | S3: =SUM(I3:R3)*20% -> 0 | T3: 1 | U3: =+SUM(I3:S3) -> 0 | V3: =U3*T3 -> 0
A4: 2 | B4: 4332033201 | C4: ADJUSTING FLAT CAMMA 720 | E4: 0 | F4: 0 | G4: 0 | H4: =+E4*F4*G4*8.55/1000000 -> 0 | I4: 0 | J4: 0 | K4: 0 | L4: 0 | M4: 0 | N4: 0 | O4: 0 | P4: 0 | Q4: 0 | R4: =H4*30 -> 0 | S4: =SUM(I4:R4)*20% -> 0 | T4: 1 | U4: 21526 | V4: =U4*T4 -> 21526
A5: 3 | B5: 4326153101 | C5: GRIP CAM 720 | E5: 0 | F5: 0 | G5: 0 | H5: =+E5*F5*G5*8.55/1000000 -> 0 | I5: 0 | J5: 0 | K5: 0 | L5: 0 | M5: 0 | N5: 0 | O5: 0 | P5: 0 | Q5: 0 | R5: =H5*30 -> 0 | S5: =SUM(I5:R5)*20% -> 0 | T5: 2 | U5: 4462 | V5: =U5*T5 -> 8924
A6: 4 | B6: 193801 | C6: SCREW ISO4017-M10X020-A2-70 | E6: 0 | F6: 0 | G6: 0 | H6: =+E6*F6*G6*8.55/1000000 -> 0 | I6: 22 | J6: 0 | K6: 0 | L6: 0 | M6: 0 | N6: 0 | O6: 0 | P6: 0 | Q6: 0 | R6: =H6*30 -> 0 | S6: =SUM(I6:R6)*20% -> 4.4 | T6: 3 | U6: =+SUM(I6:S6) -> 26.4 | V6: =U6*T6 -> 79.2
A7: 5 | B7: 179634 | C7: WASHER DIN7349-L10-A2 | E7: 0 | F7: 0 | G7: 0 | H7: =+E7*F7*G7*8.55/1000000 -> 0 | I7: 12 | J7: 0 | K7: 0 | L7: 0 | M7: 0 | N7: 0 | O7: 0 | P7: 0 | Q7: 0 | R7: =H7*30 -> 0 | S7: =SUM(I7:R7)*20% -> 2.4 | T7: 7 | U7: =+SUM(I7:S7) -> 14.4 | V7: =U7*T7 -> 100.8
A8: 6 | B8: 193803 | C8: SCREW ISO4017-M10X045-A2-70 | E8: 0 | F8: 0 | G8: 0 | H8: =+E8*F8*G8*8.55/1000000 -> 0 | I8: 45 | J8: 0 | K8: 0 | L8: 0 | M8: 0 | N8: 0 | O8: 0 | P8: 0 | Q8: 0 | R8: =H8*30 -> 0 | S8: =SUM(I8:R8)*20% -> 9 | T8: 4 | U8: =+SUM(I8:S8) -> 54 | V8: =U8*T8 -> 216
A9: 7 | B9: 4326493701 | C9: SPACER | E9: 0 | F9: 0 | G9: 0 | H9: =+E9*F9*G9*8.55/1000000 -> 0 | I9: =H9*320 -> 0 | J9: 0 | K9: 0 | L9: 0 | M9: 0 | N9: 0 | O9: 0 | P9: 0 | Q9: 0 | R9: =H9*30 -> 0 | S9: =SUM(I9:R9)*20% -> 0 | T9: 4 | U9: 200 | V9: =U9*T9 -> 800
A10: 8 | B10: 80000HSP008 | C10: ELASTIC PIN | E10: 0 | F10: 0 | G10: 0 | H10: =+E10*F10*G10*8.55/1000000 -> 0 | I10: 22 | J10: 0 | K10: 0 | L10: 0 | M10: 0 | N10: 0 | O10: 0 | P10: 0 | Q10: 0 | R10: =H10*30 -> 0 | S10: =SUM(I10:R10)*20% -> 4.4 | T10: 4 | U10: =+SUM(I10:S10) -> 26.4 | V10: =U10*T10 -> 105.6
V11: =SUM(V3:V10) -> 31751.6
U12: Assembly Cost | V12: =V11*5% -> 1587.58
U13: Total | V13: =SUM(V11:V12) -> 33339.18
